ERROR 2022-09-09 09:59:42,087 log Internal Server Error: /api/japan/
Traceback (most recent call last):
  File "C:\Users\shiva\environment\assignenv\lib\site-packages\django\core\handlers\exception.py", line 47, in inner
    response = get_response(request)
  File "C:\Users\shiva\environment\assignenv\lib\site-packages\django\core\handlers\base.py", line 181, in _get_response
    response = wrapped_callback(request, *callback_args, **callback_kwargs)
  File "C:\Users\shiva\environment\assignenv\lib\site-packages\django\views\decorators\csrf.py", line 54, in wrapped_view
    return view_func(*args, **kwargs)
  File "C:\Users\shiva\environment\assignenv\lib\site-packages\django\views\generic\base.py", line 70, in view
    return self.dispatch(request, *args, **kwargs)
  File "C:\Users\shiva\environment\assignenv\lib\site-packages\rest_framework\views.py", line 509, in dispatch
    response = self.handle_exception(exc)
  File "C:\Users\shiva\environment\assignenv\lib\site-packages\rest_framework\views.py", line 469, in handle_exception
    self.raise_uncaught_exception(exc)
  File "C:\Users\shiva\environment\assignenv\lib\site-packages\rest_framework\views.py", line 480, in raise_uncaught_exception
    raise exc
  File "C:\Users\shiva\environment\assignenv\lib\site-packages\rest_framework\views.py", line 506, in dispatch
    response = handler(request, *args, **kwargs)
TypeError: delete() got an unexpected keyword argument 'slug'
ERROR 2022-09-09 09:59:42,090 basehttp "DELETE /api/japan/ HTTP/1.1" 500 90341
ERROR 2022-09-09 09:59:52,130 log Internal Server Error: /api/japan/
Traceback (most recent call last):
  File "C:\Users\shiva\environment\assignenv\lib\site-packages\django\core\handlers\exception.py", line 47, in inner
    response = get_response(request)
  File "C:\Users\shiva\environment\assignenv\lib\site-packages\django\core\handlers\base.py", line 181, in _get_response
    response = wrapped_callback(request, *callback_args, **callback_kwargs)
  File "C:\Users\shiva\environment\assignenv\lib\site-packages\django\views\decorators\csrf.py", line 54, in wrapped_view
    return view_func(*args, **kwargs)
  File "C:\Users\shiva\environment\assignenv\lib\site-packages\django\views\generic\base.py", line 70, in view
    return self.dispatch(request, *args, **kwargs)
  File "C:\Users\shiva\environment\assignenv\lib\site-packages\rest_framework\views.py", line 509, in dispatch
    response = self.handle_exception(exc)
  File "C:\Users\shiva\environment\assignenv\lib\site-packages\rest_framework\views.py", line 469, in handle_exception
    self.raise_uncaught_exception(exc)
  File "C:\Users\shiva\environment\assignenv\lib\site-packages\rest_framework\views.py", line 480, in raise_uncaught_exception
    raise exc
  File "C:\Users\shiva\environment\assignenv\lib\site-packages\rest_framework\views.py", line 506, in dispatch
    response = handler(request, *args, **kwargs)
TypeError: delete() got an unexpected keyword argument 'slug'
ERROR 2022-09-09 09:59:52,132 basehttp "DELETE /api/japan/ HTTP/1.1" 500 90341
ERROR 2022-09-09 10:00:39,221 log Internal Server Error: /api/batangas/
Traceback (most recent call last):
  File "C:\Users\shiva\environment\assignenv\lib\site-packages\django\core\handlers\exception.py", line 47, in inner
    response = get_response(request)
  File "C:\Users\shiva\environment\assignenv\lib\site-packages\django\core\handlers\base.py", line 181, in _get_response
    response = wrapped_callback(request, *callback_args, **callback_kwargs)
  File "C:\Users\shiva\environment\assignenv\lib\site-packages\django\views\decorators\csrf.py", line 54, in wrapped_view
    return view_func(*args, **kwargs)
  File "C:\Users\shiva\environment\assignenv\lib\site-packages\django\views\generic\base.py", line 70, in view
    return self.dispatch(request, *args, **kwargs)
  File "C:\Users\shiva\environment\assignenv\lib\site-packages\rest_framework\views.py", line 509, in dispatch
    response = self.handle_exception(exc)
  File "C:\Users\shiva\environment\assignenv\lib\site-packages\rest_framework\views.py", line 469, in handle_exception
    self.raise_uncaught_exception(exc)
  File "C:\Users\shiva\environment\assignenv\lib\site-packages\rest_framework\views.py", line 480, in raise_uncaught_exception
    raise exc
  File "C:\Users\shiva\environment\assignenv\lib\site-packages\rest_framework\views.py", line 506, in dispatch
    response = handler(request, *args, **kwargs)
TypeError: delete() got an unexpected keyword argument 'slug'
ERROR 2022-09-09 10:00:39,225 basehttp "DELETE /api/batangas/ HTTP/1.1" 500 90404
ERROR 2022-09-09 10:00:44,371 log Internal Server Error: /api/batangas/
Traceback (most recent call last):
  File "C:\Users\shiva\environment\assignenv\lib\site-packages\django\core\handlers\exception.py", line 47, in inner
    response = get_response(request)
  File "C:\Users\shiva\environment\assignenv\lib\site-packages\django\core\handlers\base.py", line 181, in _get_response
    response = wrapped_callback(request, *callback_args, **callback_kwargs)
  File "C:\Users\shiva\environment\assignenv\lib\site-packages\django\views\decorators\csrf.py", line 54, in wrapped_view
    return view_func(*args, **kwargs)
  File "C:\Users\shiva\environment\assignenv\lib\site-packages\django\views\generic\base.py", line 70, in view
    return self.dispatch(request, *args, **kwargs)
  File "C:\Users\shiva\environment\assignenv\lib\site-packages\rest_framework\views.py", line 509, in dispatch
    response = self.handle_exception(exc)
  File "C:\Users\shiva\environment\assignenv\lib\site-packages\rest_framework\views.py", line 469, in handle_exception
    self.raise_uncaught_exception(exc)
  File "C:\Users\shiva\environment\assignenv\lib\site-packages\rest_framework\views.py", line 480, in raise_uncaught_exception
    raise exc
  File "C:\Users\shiva\environment\assignenv\lib\site-packages\rest_framework\views.py", line 506, in dispatch
    response = handler(request, *args, **kwargs)
TypeError: delete() got an unexpected keyword argument 'slug'
ERROR 2022-09-09 10:00:44,373 basehttp "DELETE /api/batangas/ HTTP/1.1" 500 90404
ERROR 2022-09-09 10:01:17,922 log Internal Server Error: /api/batangas/
Traceback (most recent call last):
  File "C:\Users\shiva\environment\assignenv\lib\site-packages\django\core\handlers\exception.py", line 47, in inner
    response = get_response(request)
  File "C:\Users\shiva\environment\assignenv\lib\site-packages\django\core\handlers\base.py", line 181, in _get_response
    response = wrapped_callback(request, *callback_args, **callback_kwargs)
  File "C:\Users\shiva\environment\assignenv\lib\site-packages\django\views\decorators\csrf.py", line 54, in wrapped_view
    return view_func(*args, **kwargs)
  File "C:\Users\shiva\environment\assignenv\lib\site-packages\django\views\generic\base.py", line 70, in view
    return self.dispatch(request, *args, **kwargs)
  File "C:\Users\shiva\environment\assignenv\lib\site-packages\rest_framework\views.py", line 509, in dispatch
    response = self.handle_exception(exc)
  File "C:\Users\shiva\environment\assignenv\lib\site-packages\rest_framework\views.py", line 469, in handle_exception
    self.raise_uncaught_exception(exc)
  File "C:\Users\shiva\environment\assignenv\lib\site-packages\rest_framework\views.py", line 480, in raise_uncaught_exception
    raise exc
  File "C:\Users\shiva\environment\assignenv\lib\site-packages\rest_framework\views.py", line 506, in dispatch
    response = handler(request, *args, **kwargs)
TypeError: delete() got an unexpected keyword argument 'slug'
ERROR 2022-09-09 10:01:17,927 basehttp "DELETE /api/batangas/ HTTP/1.1" 500 90404
ERROR 2022-09-09 10:01:26,539 log Internal Server Error: /api/japan/
Traceback (most recent call last):
  File "C:\Users\shiva\environment\assignenv\lib\site-packages\django\core\handlers\exception.py", line 47, in inner
    response = get_response(request)
  File "C:\Users\shiva\environment\assignenv\lib\site-packages\django\core\handlers\base.py", line 181, in _get_response
    response = wrapped_callback(request, *callback_args, **callback_kwargs)
  File "C:\Users\shiva\environment\assignenv\lib\site-packages\django\views\decorators\csrf.py", line 54, in wrapped_view
    return view_func(*args, **kwargs)
  File "C:\Users\shiva\environment\assignenv\lib\site-packages\django\views\generic\base.py", line 70, in view
    return self.dispatch(request, *args, **kwargs)
  File "C:\Users\shiva\environment\assignenv\lib\site-packages\rest_framework\views.py", line 509, in dispatch
    response = self.handle_exception(exc)
  File "C:\Users\shiva\environment\assignenv\lib\site-packages\rest_framework\views.py", line 469, in handle_exception
    self.raise_uncaught_exception(exc)
  File "C:\Users\shiva\environment\assignenv\lib\site-packages\rest_framework\views.py", line 480, in raise_uncaught_exception
    raise exc
  File "C:\Users\shiva\environment\assignenv\lib\site-packages\rest_framework\views.py", line 506, in dispatch
    response = handler(request, *args, **kwargs)
TypeError: delete() got an unexpected keyword argument 'slug'
ERROR 2022-09-09 10:01:26,541 basehttp "DELETE /api/japan/ HTTP/1.1" 500 90341
ERROR 2022-09-09 10:02:00,814 log Internal Server Error: /api/batangas/
Traceback (most recent call last):
  File "C:\Users\shiva\environment\assignenv\lib\site-packages\django\core\handlers\exception.py", line 47, in inner
    response = get_response(request)
  File "C:\Users\shiva\environment\assignenv\lib\site-packages\django\core\handlers\base.py", line 181, in _get_response
    response = wrapped_callback(request, *callback_args, **callback_kwargs)
  File "C:\Users\shiva\environment\assignenv\lib\site-packages\django\views\decorators\csrf.py", line 54, in wrapped_view
    return view_func(*args, **kwargs)
  File "C:\Users\shiva\environment\assignenv\lib\site-packages\django\views\generic\base.py", line 70, in view
    return self.dispatch(request, *args, **kwargs)
  File "C:\Users\shiva\environment\assignenv\lib\site-packages\rest_framework\views.py", line 509, in dispatch
    response = self.handle_exception(exc)
  File "C:\Users\shiva\environment\assignenv\lib\site-packages\rest_framework\views.py", line 469, in handle_exception
    self.raise_uncaught_exception(exc)
  File "C:\Users\shiva\environment\assignenv\lib\site-packages\rest_framework\views.py", line 480, in raise_uncaught_exception
    raise exc
  File "C:\Users\shiva\environment\assignenv\lib\site-packages\rest_framework\views.py", line 506, in dispatch
    response = handler(request, *args, **kwargs)
TypeError: delete() got an unexpected keyword argument 'slug'
ERROR 2022-09-09 10:02:00,817 basehttp "DELETE /api/batangas/ HTTP/1.1" 500 90404
ERROR 2022-09-09 10:02:27,609 log Internal Server Error: /api/batangas/
Traceback (most recent call last):
  File "C:\Users\shiva\environment\assignenv\lib\site-packages\django\core\handlers\exception.py", line 47, in inner
    response = get_response(request)
  File "C:\Users\shiva\environment\assignenv\lib\site-packages\django\core\handlers\base.py", line 181, in _get_response
    response = wrapped_callback(request, *callback_args, **callback_kwargs)
  File "C:\Users\shiva\environment\assignenv\lib\site-packages\django\views\decorators\csrf.py", line 54, in wrapped_view
    return view_func(*args, **kwargs)
  File "C:\Users\shiva\environment\assignenv\lib\site-packages\django\views\generic\base.py", line 70, in view
    return self.dispatch(request, *args, **kwargs)
  File "C:\Users\shiva\environment\assignenv\lib\site-packages\rest_framework\views.py", line 509, in dispatch
    response = self.handle_exception(exc)
  File "C:\Users\shiva\environment\assignenv\lib\site-packages\rest_framework\views.py", line 469, in handle_exception
    self.raise_uncaught_exception(exc)
  File "C:\Users\shiva\environment\assignenv\lib\site-packages\rest_framework\views.py", line 480, in raise_uncaught_exception
    raise exc
  File "C:\Users\shiva\environment\assignenv\lib\site-packages\rest_framework\views.py", line 506, in dispatch
    response = handler(request, *args, **kwargs)
TypeError: get() got an unexpected keyword argument 'slug'
ERROR 2022-09-09 10:02:27,612 basehttp "GET /api/batangas/ HTTP/1.1" 500 90289
ERROR 2022-09-09 10:20:16,712 log Internal Server Error: /api/newyork/
Traceback (most recent call last):
  File "C:\Users\shiva\environment\assignenv\lib\site-packages\django\core\handlers\exception.py", line 47, in inner
    response = get_response(request)
  File "C:\Users\shiva\environment\assignenv\lib\site-packages\django\core\handlers\base.py", line 181, in _get_response
    response = wrapped_callback(request, *callback_args, **callback_kwargs)
  File "C:\Users\shiva\environment\assignenv\lib\site-packages\django\views\decorators\csrf.py", line 54, in wrapped_view
    return view_func(*args, **kwargs)
  File "C:\Users\shiva\environment\assignenv\lib\site-packages\django\views\generic\base.py", line 70, in view
    return self.dispatch(request, *args, **kwargs)
  File "C:\Users\shiva\environment\assignenv\lib\site-packages\rest_framework\views.py", line 509, in dispatch
    response = self.handle_exception(exc)
  File "C:\Users\shiva\environment\assignenv\lib\site-packages\rest_framework\views.py", line 469, in handle_exception
    self.raise_uncaught_exception(exc)
  File "C:\Users\shiva\environment\assignenv\lib\site-packages\rest_framework\views.py", line 480, in raise_uncaught_exception
    raise exc
  File "C:\Users\shiva\environment\assignenv\lib\site-packages\rest_framework\views.py", line 506, in dispatch
    response = handler(request, *args, **kwargs)
  File "C:\Users\shiva\environment\assignenv\lib\site-packages\rest_framework\generics.py", line 271, in delete
    return self.destroy(request, *args, **kwargs)
  File "C:\Users\shiva\environment\assignenv\lib\site-packages\rest_framework\mixins.py", line 90, in destroy
    instance = self.get_object()
  File "C:\Users\shiva\environment\assignenv\lib\site-packages\rest_framework\generics.py", line 96, in get_object
    obj = get_object_or_404(queryset, **filter_kwargs)
  File "C:\Users\shiva\environment\assignenv\lib\site-packages\rest_framework\generics.py", line 19, in get_object_or_404
    return _get_object_or_404(queryset, *filter_args, **filter_kwargs)
  File "C:\Users\shiva\environment\assignenv\lib\site-packages\django\shortcuts.py", line 76, in get_object_or_404
    return queryset.get(*args, **kwargs)
  File "C:\Users\shiva\environment\assignenv\lib\site-packages\django\db\models\query.py", line 439, in get
    raise self.model.MultipleObjectsReturned(
weatherapp.models.City.MultipleObjectsReturned: get() returned more than one City -- it returned 2!
ERROR 2022-09-09 10:20:16,723 basehttp "DELETE /api/newyork/ HTTP/1.1" 500 116182
ERROR 2022-09-09 10:20:29,006 log Internal Server Error: /api/newyork/
Traceback (most recent call last):
  File "C:\Users\shiva\environment\assignenv\lib\site-packages\django\core\handlers\exception.py", line 47, in inner
    response = get_response(request)
  File "C:\Users\shiva\environment\assignenv\lib\site-packages\django\core\handlers\base.py", line 181, in _get_response
    response = wrapped_callback(request, *callback_args, **callback_kwargs)
  File "C:\Users\shiva\environment\assignenv\lib\site-packages\django\views\decorators\csrf.py", line 54, in wrapped_view
    return view_func(*args, **kwargs)
  File "C:\Users\shiva\environment\assignenv\lib\site-packages\django\views\generic\base.py", line 70, in view
    return self.dispatch(request, *args, **kwargs)
  File "C:\Users\shiva\environment\assignenv\lib\site-packages\rest_framework\views.py", line 509, in dispatch
    response = self.handle_exception(exc)
  File "C:\Users\shiva\environment\assignenv\lib\site-packages\rest_framework\views.py", line 469, in handle_exception
    self.raise_uncaught_exception(exc)
  File "C:\Users\shiva\environment\assignenv\lib\site-packages\rest_framework\views.py", line 480, in raise_uncaught_exception
    raise exc
  File "C:\Users\shiva\environment\assignenv\lib\site-packages\rest_framework\views.py", line 506, in dispatch
    response = handler(request, *args, **kwargs)
  File "C:\Users\shiva\environment\assignenv\lib\site-packages\rest_framework\generics.py", line 271, in delete
    return self.destroy(request, *args, **kwargs)
  File "C:\Users\shiva\environment\assignenv\lib\site-packages\rest_framework\mixins.py", line 90, in destroy
    instance = self.get_object()
  File "C:\Users\shiva\environment\assignenv\lib\site-packages\rest_framework\generics.py", line 96, in get_object
    obj = get_object_or_404(queryset, **filter_kwargs)
  File "C:\Users\shiva\environment\assignenv\lib\site-packages\rest_framework\generics.py", line 19, in get_object_or_404
    return _get_object_or_404(queryset, *filter_args, **filter_kwargs)
  File "C:\Users\shiva\environment\assignenv\lib\site-packages\django\shortcuts.py", line 76, in get_object_or_404
    return queryset.get(*args, **kwargs)
  File "C:\Users\shiva\environment\assignenv\lib\site-packages\django\db\models\query.py", line 439, in get
    raise self.model.MultipleObjectsReturned(
weatherapp.models.City.MultipleObjectsReturned: get() returned more than one City -- it returned 2!
ERROR 2022-09-09 10:20:29,006 basehttp "DELETE /api/newyork/ HTTP/1.1" 500 116182
ERROR 2022-09-09 10:21:00,183 log Internal Server Error: /api/newyork/
Traceback (most recent call last):
  File "C:\Users\shiva\environment\assignenv\lib\site-packages\django\core\handlers\exception.py", line 47, in inner
    response = get_response(request)
  File "C:\Users\shiva\environment\assignenv\lib\site-packages\django\core\handlers\base.py", line 181, in _get_response
    response = wrapped_callback(request, *callback_args, **callback_kwargs)
  File "C:\Users\shiva\environment\assignenv\lib\site-packages\django\views\decorators\csrf.py", line 54, in wrapped_view
    return view_func(*args, **kwargs)
  File "C:\Users\shiva\environment\assignenv\lib\site-packages\django\views\generic\base.py", line 70, in view
    return self.dispatch(request, *args, **kwargs)
  File "C:\Users\shiva\environment\assignenv\lib\site-packages\rest_framework\views.py", line 509, in dispatch
    response = self.handle_exception(exc)
  File "C:\Users\shiva\environment\assignenv\lib\site-packages\rest_framework\views.py", line 469, in handle_exception
    self.raise_uncaught_exception(exc)
  File "C:\Users\shiva\environment\assignenv\lib\site-packages\rest_framework\views.py", line 480, in raise_uncaught_exception
    raise exc
  File "C:\Users\shiva\environment\assignenv\lib\site-packages\rest_framework\views.py", line 506, in dispatch
    response = handler(request, *args, **kwargs)
  File "C:\Users\shiva\environment\assignenv\lib\site-packages\rest_framework\generics.py", line 268, in get
    return self.retrieve(request, *args, **kwargs)
  File "C:\Users\shiva\environment\assignenv\lib\site-packages\rest_framework\mixins.py", line 54, in retrieve
    instance = self.get_object()
  File "C:\Users\shiva\environment\assignenv\lib\site-packages\rest_framework\generics.py", line 96, in get_object
    obj = get_object_or_404(queryset, **filter_kwargs)
  File "C:\Users\shiva\environment\assignenv\lib\site-packages\rest_framework\generics.py", line 19, in get_object_or_404
    return _get_object_or_404(queryset, *filter_args, **filter_kwargs)
  File "C:\Users\shiva\environment\assignenv\lib\site-packages\django\shortcuts.py", line 76, in get_object_or_404
    return queryset.get(*args, **kwargs)
  File "C:\Users\shiva\environment\assignenv\lib\site-packages\django\db\models\query.py", line 439, in get
    raise self.model.MultipleObjectsReturned(
weatherapp.models.City.MultipleObjectsReturned: get() returned more than one City -- it returned 2!
ERROR 2022-09-09 10:21:00,186 basehttp "GET /api/newyork/ HTTP/1.1" 500 116153
ERROR 2022-09-09 10:31:42,628 log Internal Server Error: /api/newyork/
Traceback (most recent call last):
  File "C:\Users\shiva\environment\assignenv\lib\site-packages\django\core\handlers\exception.py", line 47, in inner
    response = get_response(request)
  File "C:\Users\shiva\environment\assignenv\lib\site-packages\django\core\handlers\base.py", line 181, in _get_response
    response = wrapped_callback(request, *callback_args, **callback_kwargs)
  File "C:\Users\shiva\environment\assignenv\lib\site-packages\django\views\decorators\csrf.py", line 54, in wrapped_view
    return view_func(*args, **kwargs)
  File "C:\Users\shiva\environment\assignenv\lib\site-packages\django\views\generic\base.py", line 70, in view
    return self.dispatch(request, *args, **kwargs)
  File "C:\Users\shiva\environment\assignenv\lib\site-packages\rest_framework\views.py", line 509, in dispatch
    response = self.handle_exception(exc)
  File "C:\Users\shiva\environment\assignenv\lib\site-packages\rest_framework\views.py", line 469, in handle_exception
    self.raise_uncaught_exception(exc)
  File "C:\Users\shiva\environment\assignenv\lib\site-packages\rest_framework\views.py", line 480, in raise_uncaught_exception
    raise exc
  File "C:\Users\shiva\environment\assignenv\lib\site-packages\rest_framework\views.py", line 506, in dispatch
    response = handler(request, *args, **kwargs)
  File "C:\Users\shiva\environment\assignenv\lib\site-packages\rest_framework\generics.py", line 271, in delete
    return self.destroy(request, *args, **kwargs)
  File "C:\Users\shiva\environment\assignenv\lib\site-packages\rest_framework\mixins.py", line 90, in destroy
    instance = self.get_object()
  File "C:\Users\shiva\environment\assignenv\lib\site-packages\rest_framework\generics.py", line 96, in get_object
    obj = get_object_or_404(queryset, **filter_kwargs)
  File "C:\Users\shiva\environment\assignenv\lib\site-packages\rest_framework\generics.py", line 19, in get_object_or_404
    return _get_object_or_404(queryset, *filter_args, **filter_kwargs)
  File "C:\Users\shiva\environment\assignenv\lib\site-packages\django\shortcuts.py", line 76, in get_object_or_404
    return queryset.get(*args, **kwargs)
  File "C:\Users\shiva\environment\assignenv\lib\site-packages\django\db\models\query.py", line 439, in get
    raise self.model.MultipleObjectsReturned(
weatherapp.models.City.MultipleObjectsReturned: get() returned more than one City -- it returned 3!
ERROR 2022-09-09 10:31:42,638 basehttp "DELETE /api/newyork/ HTTP/1.1" 500 116426
ERROR 2022-09-09 10:31:56,480 log Internal Server Error: /api/newyork/
Traceback (most recent call last):
  File "C:\Users\shiva\environment\assignenv\lib\site-packages\django\core\handlers\exception.py", line 47, in inner
    response = get_response(request)
  File "C:\Users\shiva\environment\assignenv\lib\site-packages\django\core\handlers\base.py", line 181, in _get_response
    response = wrapped_callback(request, *callback_args, **callback_kwargs)
  File "C:\Users\shiva\environment\assignenv\lib\site-packages\django\views\decorators\csrf.py", line 54, in wrapped_view
    return view_func(*args, **kwargs)
  File "C:\Users\shiva\environment\assignenv\lib\site-packages\django\views\generic\base.py", line 70, in view
    return self.dispatch(request, *args, **kwargs)
  File "C:\Users\shiva\environment\assignenv\lib\site-packages\rest_framework\views.py", line 509, in dispatch
    response = self.handle_exception(exc)
  File "C:\Users\shiva\environment\assignenv\lib\site-packages\rest_framework\views.py", line 469, in handle_exception
    self.raise_uncaught_exception(exc)
  File "C:\Users\shiva\environment\assignenv\lib\site-packages\rest_framework\views.py", line 480, in raise_uncaught_exception
    raise exc
  File "C:\Users\shiva\environment\assignenv\lib\site-packages\rest_framework\views.py", line 506, in dispatch
    response = handler(request, *args, **kwargs)
  File "C:\Users\shiva\environment\assignenv\lib\site-packages\rest_framework\generics.py", line 268, in get
    return self.retrieve(request, *args, **kwargs)
  File "C:\Users\shiva\environment\assignenv\lib\site-packages\rest_framework\mixins.py", line 54, in retrieve
    instance = self.get_object()
  File "C:\Users\shiva\environment\assignenv\lib\site-packages\rest_framework\generics.py", line 96, in get_object
    obj = get_object_or_404(queryset, **filter_kwargs)
  File "C:\Users\shiva\environment\assignenv\lib\site-packages\rest_framework\generics.py", line 19, in get_object_or_404
    return _get_object_or_404(queryset, *filter_args, **filter_kwargs)
  File "C:\Users\shiva\environment\assignenv\lib\site-packages\django\shortcuts.py", line 76, in get_object_or_404
    return queryset.get(*args, **kwargs)
  File "C:\Users\shiva\environment\assignenv\lib\site-packages\django\db\models\query.py", line 439, in get
    raise self.model.MultipleObjectsReturned(
weatherapp.models.City.MultipleObjectsReturned: get() returned more than one City -- it returned 3!
ERROR 2022-09-09 10:31:56,487 basehttp "GET /api/newyork/ HTTP/1.1" 500 116397
